<?xml version="1.0"?>
<robot name="duckiebot" xmlns:xacro="http://ros.org/wiki/xacro">

  <material name="blue">
    <color rgba="0.0 0.0 0.8 1.0"/>
  </material>
  <material name="grey">
    <color rgba="0.5 0.5 0.5 1.0"/>
  </material>
  <material name="red">
    <color rgba="0.8 0.0 0.0 1.0"/>
  </material>
  <material name="indigo">
    <color rgba="0.33 0.0 0.5 1.0"/>
  </material>
  <material name="yellow">
    <color rgba="1.0 1.0 0.0 1.0"/>
  </material>
  <material name="white">
    <color rgba="1.0 1.0 1.0 1.0"/>
  </material>
  <material name="black">
    <color rgba="0.01 0.01 0.01 0.9"/>
  </material>

  <link name="base_footprint"/>

  <joint name="base_joint" type="fixed">
    <parent link="base_footprint"/>
    <child link="base_link"/>
    <origin xyz="0.0 0.0 0.03425" rpy="0 0 0"/>
  </joint>
  <link name="base_link">
    <visual>
      <origin xyz="0 0 0" rpy="0 0 0"/>
      <geometry>
        <mesh filename="package://rosrider_description/meshes/duckiebot_body.dae" scale="1 1 1"/>
      </geometry>
    </visual>
  </link>

  <joint name="wheel_left_joint" type="continuous">
    <parent link="base_link"/>
    <child link="wheel_left_link"/>
    <origin xyz="0.0 0.05 0.0" rpy="0 0 0"/>
    <axis xyz="0 1 0"/>
  </joint>
  <link name="wheel_left_link">
    <visual>
      <origin xyz="0 0 0" rpy="1.570796 0 0"/>
      <geometry>
        <mesh filename="package://rosrider_description/meshes/wheel_left.dae" scale="1 1 1"/>
      </geometry>
    </visual>
  </link>

  <joint name="wheel_right_joint" type="continuous">
    <parent link="base_link"/>
    <child link="wheel_right_link"/>
    <origin xyz="0.0 -0.05 0.0" rpy="0 0 0"/>
    <axis xyz="0 1 0"/>
  </joint>
  <link name="wheel_right_link">
    <visual>
      <origin xyz="0 0 0" rpy="1.570796 0 0"/>
      <geometry>
        <mesh filename="package://rosrider_description/meshes/wheel_right.dae" scale="1 1 1"/>
      </geometry>
    </visual>
  </link>

  <joint name="wheel_castor_joint" type="fixed">
    <parent link="base_link"/>
    <child link="wheel_castor_link"/>
    <origin xyz="-0.09185 0 -0.02425" rpy="0 0 0"/>
  </joint>

  <link name="wheel_castor_link">
    <visual>
      <origin xyz="0 0 0" rpy="0 0 0"/>
      <geometry>
        <sphere radius="0.01"/>
      </geometry>
      <material name="white"/>
    </visual>
  </link>

  <joint name="imu_joint" type="fixed">
    <parent link="base_link"/>
    <child link="imu_link"/>
    <origin xyz="0 0 0.0739" rpy="0 0 0"/>
  </joint>

  <link name="imu_link">
    <visual>
      <origin xyz="0 0 0" rpy="0 0 0"/>
      <geometry>
        <mesh filename="package://rosrider_description/meshes/fximu3e.dae" scale="1 1 1"/>
      </geometry>
    </visual>
  </link>

  <joint name="battery_joint" type="fixed">
    <parent link="base_link"/>
    <child link="battery_link"/>
    <origin xyz="-0.034057 0 0.057282" rpy="0 0 0"/>
  </joint>

  <link name="battery_link">
    <visual>
      <origin xyz="0 0 0" rpy="0 0 0"/>
      <geometry>
        <box size="0.1368 0.0639 0.016"/>
      </geometry>
      <material name="grey"/>
    </visual>
  </link>

  <joint name="camera_joint" type="fixed">
    <parent link="base_link"/>
    <child link="camera_optical_frame"/>
    <origin xyz="0.05935 0.0 0.07690" rpy="-1.87 0.0 -1.570796"/>
  </joint>

  <link name="camera_optical_frame">
    <visual>
      <origin xyz="0 0 0" rpy="0 0 0"/>
      <geometry>
        <mesh filename="package://rosrider_description/meshes/cam_stand_optical.dae" scale="1 1 1"/>
      </geometry>
      <material name="grey"/>
    </visual>
  </link>

</robot>