<?xml version="1.0" ?>
<robot name="next" xmlns:xacro="http://ros.org/wiki/xacro">

  <material name="blue">
    <color rgba="0.0 0.0 0.8 1.0"/>
  </material>
  <material name="grey">
    <color rgba="0.5 0.5 0.5 1.0"/>
  </material>
  <material name="red">
    <color rgba="0.8 0.0 0.0 1.0"/>
  </material>
  <material name="indigo">
    <color rgba="0.33 0.0 0.5 1.0"/>
  </material>
  <material name="yellow">
    <color rgba="1.0 1.0 0.0 1.0"/>
  </material>
  <material name="white">
    <color rgba="1.0 1.0 1.0 1.0"/>
  </material>
  <material name="black">
    <color rgba="0.01 0.01 0.01 0.9"/>
  </material>

  <link name="base_footprint"/>

  <joint name="base_joint" type="fixed">
    <parent link="base_footprint"/>
    <child link="base_link"/>
    <origin xyz="0.0 0.0 0.03425" rpy="0 0 0"/>
  </joint>
  <link name="base_link">
    <visual>
      <origin xyz="0 0 0" rpy="0 0 0"/>
      <geometry>
        <mesh filename="package://rosrider_description/meshes/next_urdf.dae" scale="1 1 1"/>
      </geometry>
    </visual>
  </link>

  <joint name="wheel_left_joint" type="continuous">
    <parent link="base_link"/>
    <child link="wheel_left_link"/>
    <origin xyz="0.0 0.087 0.0" rpy="-1.57 0 0"/>
    <axis xyz="0 0 1"/>
  </joint>
  <link name="wheel_left_link">
    <visual>
      <origin xyz="0 0 0" rpy="0 0 0"/>
      <geometry>
        <mesh filename="package://rosrider_description/meshes/wheel_left.dae" scale="1 1 1"/>
      </geometry>
    </visual>
  </link>

  <joint name="wheel_right_joint" type="continuous">
    <parent link="base_link"/>
    <child link="wheel_right_link"/>
    <origin xyz="0.0 -0.087 0.0" rpy="-1.57 0 0"/>
    <axis xyz="0 0 1"/>
  </joint>
  <link name="wheel_right_link">
    <visual>
      <origin xyz="0 0 0" rpy="0 0 0"/>
      <geometry>
        <mesh filename="package://rosrider_description/meshes/wheel_right.dae" scale="1 1 1"/>
      </geometry>
    </visual>
  </link>

  <joint name="wheel_steering_joint" type="continuous">
    <parent link="base_link"/>
    <child link="wheel_steering_link"/>
    <axis xyz="0 0 1"/>
    <origin xyz="-0.1842 0 -0.00875" rpy="0 0 0"/>
  </joint>
  <link name="wheel_steering_link">
  </link>

  <joint name="wheel_castor_joint" type="continuous">
    <parent link="wheel_steering_link"/>
    <child link="wheel_castor_link"/>
    <axis xyz="0 1 0"/>
    <origin xyz="-0.016 0 -0.01275" rpy="0 0 0"/>
  </joint>
  <link name="wheel_castor_link">
      <collision>
        <geometry>
          <mesh filename="package://rosrider_description/meshes/vac_wheel.stl" scale="0.001 0.001 0.001"/>
        </geometry>
      </collision>
      <visual>
        <geometry>
          <mesh filename="package://rosrider_description/meshes/vac_wheel.dae" scale="1 1 1"/>
        </geometry>
      </visual>
  </link>

  <joint name="scan_joint" type="fixed">
    <parent link="base_link"/>
    <child link="base_scan"/>
    <origin xyz="-0.1692 0.0 0.061" rpy="0 0 0"/>
  </joint>
  <link name="base_scan">
    <visual>
      <origin xyz="0 0 0" rpy="0 0 0"/>
      <geometry>
        <mesh filename="package://rosrider_description/meshes/ldlidar.dae" scale="1 1 1"/>
      </geometry>
    </visual>
  </link>

  <joint name="imu_joint" type="fixed">
    <parent link="base_link"/>
    <child link="imu_link"/>
    <origin xyz="0.0378 0.0 0.0473" rpy="0 0 0"/>
  </joint>
  <link name="imu_link">
    <visual>
      <origin xyz="0 0 0" rpy="0 0 0"/>
      <geometry>
        <mesh filename="package://rosrider_description/meshes/fximu3e.dae" scale="1 1 1"/>
      </geometry>
    </visual>
  </link>

  <joint name="battery_joint" type="fixed">
    <parent link="base_link"/>
    <child link="battery_link"/>
    <origin xyz="-0.07183 0 0.0116" rpy="0 0 0"/>
  </joint>
  <link name="battery_link">
    <visual>
      <origin xyz="0 0 0" rpy="0 0 0"/>
      <geometry>
        <box size="0.0736 0.1535 0.0276"/>
      </geometry>
      <material name="black"/>
    </visual>
  </link>

</robot>